Workbook

Sheet 参数假设
A1: SCOP 智慧社区运营平台 — 财务测算参数假设
A2: 绿色单元格为可调参数，修改后其他Sheet自动重算 | 红色单元格为计算结果
A4: 一、订阅套餐参数
A5: 参数项 | B5: 数值 | C5: 单位 | D5: 说明
A6: 安全守护包月价 | B6: 99 | C6: 元/月/户 | D6: 含烟感+门磁+SOS按钮
A7: 健康守护包月价 | B7: 199 | C7: 元/月/户 | D7: 含智能穿戴手环
A8: 全能守护包月价 | B8: 299 | C8: 元/月/户 | D8: 安全+健康全套硬件
A9: 安全包占比 | B9: 0.3 | C9: % | D9: 首年套餐结构假设
A10: 健康包占比 | B10: 0.45 | C10: % | D10: 首年套餐结构假设
A11: 全能包占比 | B11: 0.25 | C11: % | D11: 首年套餐结构假设
A12: 年付优惠折扣 | B12: 0.85 | C12: % | D12: 年付享85折
A13: 年付占比 | B13: 0.4 | C13: % | D13: 选择年付的用户比例
A14: 续费率 | B14: 0.85 | C14: % | D14: 到期续费率目标
A16: 加权月ARPU（自动计算） | B16: =B9*B6+B10*B7+B11*B8 | C16: 元/月/户 | D16: 按套餐占比加权平均
A18: 二、硬件设备成本参数
A19: 参数项 | B19: 数值 | C19: 单位 | D19: 说明
A20: 安全包设备成本 | B20: 150 | C20: 元/户 | D20: 烟感+门磁+SOS按钮批量采购
A21: 健康包设备成本 | B21: 350 | C21: 元/户 | D21: 智能穿戴手环+基础安全设备
A22: 全能包设备成本 | B22: 450 | C22: 元/户 | D22: 全套安全+健康设备
A23: 设备安装费 | B23: 50 | C23: 元/户 | D23: 上门安装调试
A24: 设备年故障率 | B24: 0.05 | C24: % | D24: 年故障更换率
A26: 加权硬件成本（含安装，自动计算） | B26: =B9*(B20+B23)+B10*(B21+B23)+B11*(B22+B23) | C26: 元/户 | D26: 按套餐占比加权
A28: 三、人力成本参数（上海薪资标准）
A29: 参数项 | B29: 数值 | C29: 单位 | D29: 说明
A30: 后端开发月薪 | B30: 35000 | C30: 元/月/人 | D30: 上海中级后端工程师
A31: 前端开发月薪 | B31: 30000 | C31: 元/月/人 | D31: 上海中级前端工程师
A32: 测试工程师月薪 | B32: 25000 | C32: 元/月/人 | D32: 上海中级测试
A33: 产品经理月薪 | B33: 30000 | C33: 元/月/人 | D33: 上海中级产品
A34: UI/UX设计师月薪 | B34: 28000 | C34: 元/月/人 | D34: 上海中级设计
A35: 项目经理月薪 | B35: 32000 | C35: 元/月/人 | D35: 上海中级PM
A36: 运维/DevOps月薪 | B36: 30000 | C36: 元/月/人 | D36: 上海中级运维
A37: 社保公积金系数 | B37: 1.3 | C37: 倍 | D37: 含五险一金及福利
A38: 后端人数 | B38: 3 | C38: 人 | D38: IoT对接1+业务2
A39: 前端人数 | B39: 2 | C39: 人 | D39: Web1+小程序1
A40: 其他岗位各 | B40: 1 | C40: 人 | D40: 测试/产品/设计/PM/运维各1人
A41: 研发工期 | B41: 6 | C41: 月 | D41: M0-M8约26周
A43: 月人力总成本（自动计算） | B43: =B37*(B30*B38+B31*B39+(B32+B33+B34+B35+B36)*B40) | C43: 元/月 | D43: 9人团队含五险一金
A44: 研发期总人力成本（自动计算） | B44: =B43*B41 | C44: 元 | D44: 月人力×研发工期
A46: 四、运营成本参数
A47: 参数项 | B47: 数值 | C47: 单位 | D47: 说明
...

Sheet 首年月度测算
A1: SCOP 首年月度财务测算（M1-M12）
A3: 项目 | B3: M1 | C3: M2 | D3: M3 | E3: M4 | F3: M5 | G3: M6 | H3: M7 | I3: M8 | J3: M9 | K3: M10 | L3: M11 | M3: M12 | N3: 全年合计
A4: 一、收入
A5: 月末累计户数 | B5: ='参数假设'!B62 | C5: ='参数假设'!C62 | D5: ='参数假设'!D62 | E5: ='参数假设'!E62 | F5: ='参数假设'!F62 | G5: ='参数假设'!G62 | H5: ='参数假设'!H62 | I5: ='参数假设'!I62 | ... M5: ='参数假设'!M62 | N5: =M5
A6: 当月新增户数 | B6: =B5 | C6: =C5-B5 | D6: =D5-C5 | E6: =E5-D5 | F6: =F5-E5 | G6: =G5-F5 | H6: =H5-G5 | I6: =I5-H5 | J6: =J5-I5 | ... M6: =M5-L5 | N6: =SUM(B6:M6)
A7: 月订阅收入 | B7: =B5*'参数假设'!B16 | C7: =C5*'参数假设'!B16 | D7: =D5*'参数假设'!B16 | E7: =E5*'参数假设'!B16 | F7: =F5*'参数假设'!B16 | G7: =G5*'参数假设'!B16 | H7: =H5*'参数假设'!B16 | I7: =I5*'参数假设'!B16 | J7: =J5*'参数假设'!B16 | K7: =K5*'参数假设'!B16 | L7: =L5*'参数假设'!B16 | M7: =M5*'参数假设'!B16 | N7: =SUM(B7:M7)
A9: 二、成本
A10: 人力成本（9人团队） | B10: ='参数假设'!B43 | C10: ='参数假设'!B43 | D10: ='参数假设'!B43 | E10: ='参数假设'!B43 | F10: ='参数假设'!B43 | G10: ='参数假设'!B43 | H10: ='参数假设'!B43 | I10: ='参数假设'!B43 | J10: ='参数假设'!B43 | K10: ='参数假设'!B43 | L10: ='参数假设'!B43 | M10: ='参数假设'!B43 | N10: =SUM(B10:M10)
A11: 硬件采购+安装 | B11: =B6*'参数假设'!B26 | C11: =C6*'参数假设'!B26 | D11: =D6*'参数假设'!B26 | E11: =E6*'参数假设'!B26 | F11: =F6*'参数假设'!B26 | G11: =G6*'参数假设'!B26 | H11: =H6*'参数假设'!B26 | I11: =I6*'参数假设'!B26 | J11: =J6*'参数假设'!B26 | K11: =K6*'参数假设'!B26 | L11: =L6*'参数假设'!B26 | M11: =M6*'参数假设'!B26 | N11: =SUM(B11:M11)
A12: 运营固定成本 | B12: ='参数假设'!B58 | C12: ='参数假设'!B58 | D12: ='参数假设'!B58 | E12: ='参数假设'!B58 | F12: ='参数假设'!B58 | G12: ='参数假设'!B58 | H12: ='参数假设'!B58 | I12: ='参数假设'!B58 | J12: ='参数假设'!B58 | K12: ='参数假设'!B58 | L12: ='参数假设'!B58 | M12: ='参数假设'!B58 | N12: =SUM(B12:M12)
A13: 成本合计 | B13: =B10+B11+B12 | C13: =C10+C11+C12 | D13: =D10+D11+D12 | E13: =E10+E11+E12 | F13: =F10+F11+F12 | G13: =G10+G11+G12 | H13: =H10+H11+H12 | I13: =I10+I11+I12 | ... M13: =M10+M11+M12 | N13: =SUM(B13:M13)
A15: 三、利润分析
A16: 月净利润 | B16: =B7-B13 | C16: =C7-C13 | D16: =D7-D13 | E16: =E7-E13 | F16: =F7-F13 | G16: =G7-G13 | H16: =H7-H13 | I16: =I7-I13 | ... M16: =M7-M13 | N16: =SUM(B16:M16)
A17: 累计利润 | B17: =B16 | C17: =B17+C16 | D17: =C17+D16 | E17: =D17+E16 | F17: =E17+F16 | G17: =F17+G16 | H17: =G17+H16 | I17: =H17+I16 | J17: =I17+J16 | ... M17: =L17+M16 | N17: =M17
A18: 月利润率 | B18: =IF(B7=0,0,B16/B7) | C18: =IF(C7=0,0,C16/C7) | D18: =IF(D7=0,0,D16/D7) | E18: =IF(E7=0,0,E16/E7) | F18: =IF(F7=0,0,F16/F7) | G18: =IF(G7=0,0,G16/G7) | H18: =IF(H7=0,0,H16/H7) | I18: =IF(I7=0,0,I16/I7) | ... M18: =IF(M7=0,0,M16/M7) | N18: =N16/N7
A20: 四、关键结论
A21: 首年总收入 | B21: =N7 | C21: 元
A22: 首年总成本 | B22: =N13 | C22: 元
A23: 首年净利润 | B23: =N16 | C23: 元
A24: 首年研发人力投入 | B24: =N10 | C24: 元
A25: 首年硬件投入 | B25: =N11 | C25: 元
A26: 首年运营成本 | B26: =N12 | C26: 元
A27: 首年MRR（M12月订阅收入） | B27: =M7 | C27: 元

Sheet 三年预测
A1: SCOP 三年财务预测
A3: 项目 | B3: Y1（首年） | C3: Y2（次年） | D3: Y3（第三年） | E3: 三年合计
A4: 年末累计户数 | B4: ='参数假设'!B66 | C4: ='参数假设'!B67 | D4: ='参数假设'!B68 | E4: —
A5: 年平均户数 | B5: =B4/2 | C5: =(B4+C4)/2 | D5: =(C4+D4)/2 | E5: —
A7: 一、收入
A8: 订阅收入 | B8: =B5*'参数假设'!B16*12 | C8: =C5*'参数假设'!B16*12 | D8: =D5*'参数假设'!B16*12 | E8: =SUM(B8:D8)
A9: V2模块增量收入 | B9: 0 | C9: =C8*'参数假设'!B69 | D9: =D8*'参数假设'!B70 | E9: =SUM(B9:D9)
A10: 总收入 | B10: =B8+B9 | C10: =C8+C9 | D10: =D8+D9 | E10: =SUM(B10:D10)
A12: 二、成本
A13: 人力成本 | B13: ='参数假设'!B43*12 | C13: =B13*'P'!B71 | D13: =B13*'P'!B72 | E13: =SUM(B13:D13)
A14: 硬件采购+安装 | B14: =B4*2*'参数假设'!B26 | C14: =(C4-B4)*'参数假设'!B26 | D14: =(D4-C4)*'参数假设'!B26 | E14: =SUM(B14:D14)
A15: 运营成本 | B15: ='参数假设'!B58*12 | C15: =B15*'P'!B71 | D15: =B15*'P'!B72 | E15: =SUM(B15:D15)
A16: 成本合计 | B16: =B13+B14+B15 | C16: =C13+C14+C15 | D16: =D13+D14+D15 | E16: =SUM(B16:D16)
A18: 三、利润与回报
A19: 年净利润 | B19: =B10-B16 | C19: =C10-C16 | D19: =D10-D16 | E19: =SUM(B19:D19)
A20: 累计净利润 | B20: =B19 | C20: =B20+C19 | D20: =C20+D19 | E20: =D20
A21: 净利率 | B21: =IF(B10=0,0,B19/B10) | C21: =IF(C10=0,0,C19/C10) | D21: =IF(D10=0,0,D19/D10) | E21: =E19/E10
A23: 四、投资回报指标
A24: 初始投资（Y1总成本） | B24: =B16
A25: 三年累计净利润 | B25: =E19
A26: 折现率 | B26: ='参数假设'!B73
A27: NPV（净现值） | B27: =NPV(B26,B19:D19)
A28: IRR（内部收益率） | B28: =IFERROR(IRR(B19:D19),"待盈利")

Sheet 盈亏平衡分析
A1: SCOP 盈亏平衡分析
A3: 月户数 | B3: 月订阅收入 | C3: 月固定成本 | D3: 月变动成本 | E3: 月总成本 | F3: 月利润
A4: 500 | B4: =A4*'参数假设'!B16 | C4: ='参数假设'!B43+'参数假设'!B58 | D4: =A4*'参数假设'!B26/24+A4*0.05*'参数假设'!B26/12 | E4: =C4+D4 | F4: =B4-E4
A5: 1000 | B5: =A5*'参数假设'!B16 | C5: ='参数假设'!B43+'参数假设'!B58 | D5: =A5*'参数假设'!B26/24+A5*0.05*'参数假设'!B26/12 | E5: =C5+D5 | F5: =B5-E5
A6: 1500 | B6: =A6*'参数假设'!B16 | C6: ='参数假设'!B43+'参数假设'!B58 | D6: =A6*'参数假设'!B26/24+A6*0.05*'参数假设'!B26/12 | E6: =C6+D6 | F6: =B6-E6
A7: 2000 | B7: =A7*'参数假设'!B16 | C7: ='参数假设'!B43+'参数假设'!B58 | D7: =A7*'参数假设'!B26/24+A7*0.05*'参数假设'!B26/12 | E7: =C7+D7 | F7: =B7-E7
A8: 3000 | B8: =A8*'参数假设'!B16 | C8: ='参数假设'!B43+'参数假设'!B58 | D8: =A8*'参数假设'!B26/24+A8*0.05*'参数假设'!B26/12 | E8: =C8+D8 | F8: =B8-E8
A9: 5000 | B9: =A9*'参数假设'!B16 | C9: ='参数假设'!B43+'参数假设'!B58 | D9: =A9*'参数假设'!B26/24+A9*0.05*'参数假设'!B26/12 | E9: =C9+D9 | F9: =B9-E9
A10: 8000 | B10: =A10*'参数假设'!B16 | C10: ='参数假设'!B43+'参数假设'!B58 | D10: =A10*'参数假设'!B26/24+A10*0.05*'参数假设'!B26/12 | E10: =C10+D10 | F10: =B10-E10
A11: 10000 | B11: =A11*'参数假设'!B16 | C11: ='参数假设'!B43+'参数假设'!B58 | D11: =A11*'参数假设'!B26/24+A11*0.05*'参数假设'!B26/12 | E11: =C11+D11 | F11: =B11-E11
A13: 盈亏平衡分析结论
A14: 月固定成本（人力+运营） | B14: ='参数假设'!B43+'参数假设'!B58 | C14: 元/月
A15: 加权月ARPU | B15: ='参数假设'!B16 | C15: 元/户/月
A16: 单位边际贡献 | B16: ='参数假设'!B16-('参数假设'!B26/24+0.05*'参数假设'!B26/12) | C16: 元/户/月
A17: 盈亏平衡户数（理论） | B17: =('参数假设'!B43+'参数假设'!B58)/('参数假设'!B16-('参数假设'!B26/24+0.05*'参数假设'!B26/12)) | C17: 户
A18: 对应社区数（约100户/社区） | B18: =ROUNDUP(('参数假设'!B43+'参数假设'!B58)/('参数假设'!B16-('参数假设'!B26/24+0.05*'参数假设'!B26/12))/100,0) | C18: 个社区
